package exceptionsfun erroneousCode() {    val i = "1$".toInt()    /**     *     * Exception in thread "main" java.lang.NumberFormatException: For input string: "1$"     * 	at java.base/java.lang.NumberFormatException.forInputString(NumberFormatException.java:67)     * 	at java.base/java.lang.Integer.parseInt(Integer.java:668)     * 	at java.base/java.lang.Integer.parseInt(Integer.java:786)     * 	at exceptions.ToIntExceptionKt.erroneousCode(ToIntException.kt:5)     * 	at exceptions.ToIntExceptionKt.main(ToIntException.kt:9)     * 	at exceptions.ToIntExceptionKt.main(ToIntException.kt)     *     * 	이런 예외가 뜸     */}fun main() {    erroneousCode()}